#VRML_SIM R2020b utf8
# license: Apache License 2.0
# license url: http://www.apache.org/licenses/LICENSE-2.0
# tags: static
# More info here: https://www.youtube.com/c/soft-illusion
# Robotsense

PROTO RobotSense [
    field SFVec3f    translation  0 0.0198 0
    field SFRotation rotation     0 1 0 2.3495
    field SFString   controller   "<extern>"
  ]
  {
    Robot {
  translation IS translation
  rotation IS rotation
  controller IS controller
  children [
    DistanceSensor {
      type "infra-red"
      translation -0.03 -0.02 0.1
      rotation 0 0 -1 1.5708
      children [
        Shape {
          appearance PBRAppearance {
            baseColor 0.988235 0.913725 0.309804
          }
          geometry Box {
            size 0.01 0.01 0.01
          }
        }
      ]
      name "ls_right"
      lookupTable [
        0 1000 0
        0.1 0 0
      ]
    }
    DistanceSensor {
      type "infra-red"
      translation -6.74634e-14 -0.02 0.1
      rotation 0 0 -1 1.5708
      children [
        Shape {
          appearance PBRAppearance {
            baseColor 0.988235 0.913725 0.309804
          }
          geometry Box {
            size 0.01 0.01 0.01
          }
        }
      ]
      name "ls_mid"
      lookupTable [
        0 1000 0
        0.1 0 0
      ]
    }
    DistanceSensor {
      type "infra-red"
      translation 0.03 -0.02 0.1
      rotation 0 0 -1 1.5708
      children [
        Shape {
          appearance PBRAppearance {
            baseColor 0.988235 0.913725 0.309804
          }
          geometry Box {
            size 0.01 0.01 0.01
          }
        }
      ]
      name "ls_left"
      lookupTable [
        0 1000 0
        0.1 0 0
      ]
    }
    DEF Body Shape {
      appearance PBRAppearance {
        baseColor 1 0 0
        metalness 0
      }
      geometry Box {
        size 0.1 0.05 0.2
      }
    }
    HingeJoint {
      jointParameters HingeJointParameters {
        position 24.639778010956185
        anchor 0.06 0 0.05
      }
      device [
        RotationalMotor {
          name "wheel1"
        }
      ]
      endPoint DEF wheel1 Solid {
        translation 0.06 0 0.05
        rotation -0.2372178203750054 0.23702899264272692 0.9420960473026654 1.6296141054596442
        children [
          DEF Wheel Shape {
            appearance PBRAppearance {
              baseColor 0 1 0
              metalness 0
            }
            geometry Cylinder {
              height 0.02
              radius 0.04
            }
          }
        ]
        name "wheel1"
        boundingObject USE Wheel
        physics DEF Wheel_Ph Physics {
        }
      }
    }
    HingeJoint {
      jointParameters HingeJointParameters {
        position 6.591807654192812
        anchor -0.06 0 0.05
      }
      device [
        RotationalMotor {
          name "wheel2"
        }
      ]
      endPoint DEF wheel2 Solid {
        translation -0.06 0 0.05
        rotation -0.15203380324924576 0.15191278283749135 -0.9766310608823265 4.689540972681517
        children [
          USE Wheel
        ]
        name "wheel2"
        boundingObject USE Wheel
        physics USE Wheel_Ph
      }
    }
    HingeJoint {
      jointParameters HingeJointParameters {
        position 24.639778178135185
        anchor 0.06 0 -0.05
      }
      device [
        RotationalMotor {
          name "wheel3"
        }
      ]
      endPoint DEF wheel3 Solid {
        translation 0.06 0 -0.05
        rotation -0.23721774599786627 0.2370289183247925 0.9420960847288723 1.629614065801813
        children [
          USE Wheel
        ]
        name "wheel3"
        boundingObject USE Wheel
        physics USE Wheel_Ph
      }
    }
    HingeJoint {
      jointParameters HingeJointParameters {
        position 6.59180757522415
        anchor -0.06 0 -0.05
      }
      device [
        RotationalMotor {
          name "wheel4"
        }
      ]
      endPoint DEF wheel4 Solid {
        translation -0.06 0 -0.05
        rotation -0.15203376554893583 0.15191274516719103 -0.9766310726107271 4.6895409846874205
        children [
          USE Wheel
        ]
        name "wheel4"
        boundingObject USE Wheel
        physics USE Wheel_Ph
      }
    }
    DistanceSensor {
      translation -0.02 0 0.1
      rotation 0 1 0 -1.87
      children [
        DEF sensor Shape {
          appearance PBRAppearance {
          }
          geometry DEF Sensor Box {
            size 0.01 0.01 0.01
          }
        }
      ]
      name "ds_right"
    }
    DistanceSensor {
      translation 0.02 0 0.1
      rotation 0 1 0 -1.27
      children [
        USE sensor
      ]
      name "ds_left"
    }
  ]
  name "Robot_sense"
  boundingObject USE Body
  physics Physics {
  }
}
}
