<?xml version="1.0" ?>
<robot name="Tiago Webots">
    <link name="base_link" />

    <joint name="wheel_right_joint" type="continuous">
        <parent link="base_link" />
        <child link="wheel_right_link" />
    </joint>

    <link name="wheel_right_link" />

    <joint name="wheel_left_joint" type="continuous">
        <parent link="base_link" />
        <child link="wheel_left_link" />
    </joint>

    <link name="wheel_left_link" />

    <webots>
        <device reference="hokuyo" type="Lidar">
            <ros>
                <enabled>true</enabled>
                <updateRate>10</updateRate>
                <topicName>/scan</topicName>
                <alwaysOn>true</alwaysOn>
                <frameName>hokuyo</frameName>
            </ros>
        </device>

        <plugin type="webots_ros2_control::Ros2Control" />
    </webots>

    <ros2_control name="WebotsControl" type="system">
        <hardware>
            <plugin>webots_ros2_control::Ros2ControlSystem</plugin>
        </hardware>
        <joint name="wheel_right_joint">
            <state_interface name="position"/>
            <command_interface name="velocity"/>
        </joint>
        <joint name="wheel_left_joint">
            <state_interface name="position"/>
            <command_interface name="velocity"/>
        </joint>
    </ros2_control>
</robot>
